Workbook

Sheet Project Data
A1: Project Name | B1: ...
A3: Online team meeting | B3: https://tu-berlin.zoom-x.de/j/64327398600?pwd=iKF2e9D7PEM8Q552cgabakS0O6L9xa.1
A5: Production system (if any) | B5: http://amos.b-iq.net/
A6: Test system (if any) | B6: ...
A8: GitHub repository | B8: https://github.com/amosproj/amos2025ss02-building-documentation-management-system
A9: GitHub feature board | B9: https://github.com/orgs/amosproj/projects/80/views/2
A10: GitHub imp-squared backlog | B10: https://github.com/orgs/amosproj/projects/84
A12: Team T-shirt (white) | B12: https://www.shirtinator.de/loadBasket/vNV5XYUVMtq
A13: Team T-shirt (black) | B13: https://www.shirtinator.de/loadBasket/nQ9JYKa8F3W
A15: Additional materials | B15: ...
A17: Team maling list | B17: oss-amos-proj2@lists.fau.de

Sheet Project Team
A1: Last Name | B1: First Name | C1: GitHub User Name | D1: Email Address
A2: Kurtz | B2: Daniel | C2: daku-de | D2: daniel.kurtz@fau.de
A3: Deli | B3: Deniz | C3: ddeli | D3: d.deli@campus.tu-berlin.de
A4: Egge | B4: Carl | C4: carl-egge | D4: c.egge@campus.tu-berlin.de
A5: Halder | B5: Arpita | C5: arpita739 | D5: arpita.halder@fau.de
A6: Kazi | B6: Masudur Rahaman | C6: kamsur | D6: masudur.r.kazi@fau.de
A7: Almalla | B7: Nirmin | C7: Nirmin96 | D7: nirmin.almalla@campus.tu-berlin.de
A8: Ouabo | B8: Samuel | C8: so77nava | D8: samuel.ouabo@fau.de
A9: Billah | B9: Masum | C9: masum-abid | D9: masum.billah@fau.de
A10: Hussain | B10: Syed Affan | C10: syedaffan10 | D10: affan.hussain@fau.de
A11: Djamen | B11: Bastiane | C11: bastydjamen | D11: eugenie.djamen@fau.de

Sheet Role Assignments
C1: Product Owner
A2: # | B2: Meeting Day | C2: Review | D2: Planning | E2: Software Developer | F2: Release Manager | G2: Scrum Master | H2: Comment
A3: 1 | B3: 45763 | D3: Daniel | E3: Everyone else | F3: N/A | G3: Deniz
A4: 2 | B4: =B3+7 -> 45770 | C4: Daniel | D4: Carl | E4: Everyone else | F4: Arpita | G4: Deniz
A5: 3 | B5: =B4+7 -> 45777 | C5: Carl | D5: Daniel | E5: Everyone else | F5: Masudur Rahaman | G5: Deniz
A6: 4 | B6: =B5+7 -> 45784 | C6: Daniel | D6: Carl | E6: Everyone else | F6: Samuel | G6: Deniz
A7: 5 | B7: =B6+7 -> 45791 | C7: Carl | D7: Daniel | E7: Everyone else | F7: Masum | G7: Deniz
A8: 6 | B8: =B7+7 -> 45798 | C8: Daniel | D8: Carl | E8: Everyone else | F8: Syed Affan | G8: Deniz
A9: 7 | B9: =B8+7 -> 45805 | C9: Carl | D9: Daniel | E9: Everyone else | F9: Bastiane | G9: Deniz | H9: Mid-term due
A10: 8 | B10: =B9+7 -> 45812 | C10: Daniel | D10: Carl | E10: Everyone else | F10: Arpita | G10: Deniz
A11: 9 | B11: =B10+7 -> 45819 | C11: Carl | D11: Daniel | E11: Everyone else | F11: Masudur Rahaman | G11: Deniz
A12: 10 | B12: =B11+7 -> 45826 | C12: Daniel | D12: Carl | E12: Everyone else | F12: Samuel | G12: Deniz
A13: 11 | B13: =B12+7 -> 45833 | C13: Carl | D13: Daniel | E13: Everyone else | F13: Masum | G13: Deniz
A14: 12 | B14: =B13+7 -> 45840 | C14: Daniel | D14: Carl | E14: Everyone else | F14: Syed Affan | G14: Deniz
A15: 13 | B15: =B14+7 -> 45847 | C15: Carl | D15: Daniel | E15: Everyone else | F15: Bastiane | G15: Deniz
A16: 14 | B16: =B15+7 -> 45854 | C16: Daniel | D16: Carl | E16: Everyone else | F16: Arpita | G16: Deniz | H16: Demo day!
A17: 15 | B17: =B16+7 -> 45861 | C17: Carl | D17: Daniel | E17: Everyone else | F17: Masudur Rahaman | G17: Deniz | H17: Retrospective
A19: Product owners, software developers, and Scurm Master are set and ideally don't change over time; the critical part is the Release Manager role you need to define here

Sheet Team Contract
A1: Goals | B1: Deliver a product that meets the stakeholder requirements.
B2: Everybody in the team wants to gain some new knowledge.
B3: Every team member should have fun during the project.
B4: Coming up with innovative solutions using modern technology.
B5: Develop our skills in teamwork and communication.
A7: Meeting norms | B7: We meet every Wednesday in the team meeting.
B8: POs will have weekly meetings with the stakeholder which are optional for the SDs.
B9: Everybody should be on time for the team meeting. If you are late or unavailable please inform the group beforehand through the defined communication channels.
B10: We practice a respectful and non-disciminative communication with all team members.
B11: Everyone should do their best to participate with Camera and Microphone turned on in the team meetings.
B12: Meetings will follow a clear structure that is quickly presented at the beginning of the meeting.
A14: Working norms | B14: We communicate or problems with the group and help colleagues that are stuck.
B15: We will follow a common Git Flow that will be defined by the SDs and follows industry best-practices.
B16: Commit often and use clear commit messages to avoid unnecessary conflicts.
B17: We will always use pull requests and code reviews instead of force pushes to improve coding quality.
A19: Coordination norms | B19: The POs are responsible for allocating assignments.
B20: The POs will alternatingly moderate the team meetings. The SM is responsible for keeping the team meetings on track.
A22: Communication norms | B22: We will use Discord as technical channel for programming topics.
B23: The Email list and Stand Up Email will be for organizational communication and announcements.
B24: Everybody should check these channels daily.
B25: We use english as a working language.
B26: The WhatsApp group is an additional optional channel for group conversations.
A28: Consideration norms | B28: No side conversation and technical conversations during the team meeting.
B29: For team decisions and disagreements an anonymous vote will be held and the majority decides.
A31: Cont. improvement norms | B31: Stand Up Emails and Hapiness Index will be used to track team work.
B32: No pull requests should be accepted without feedback from at least one other team member (Positive feedback is welcome).
B33: We practice open feedback culture and continously improve our working environment.
A35: Rewards | B35: By delivering on time everyone can reward themself with a free weekend.
A37: Sanctions | B37: We define no sanctions.
A39: Signatures
A41: Scrum Master | B41: Deniz Deli
A42: Product owner | B42: Daniel Kurtz
A43: Product owner | B43: Carl Egge
A44: Software developer | B44: Masudur Rahaman Kazi
A45: Software developer | B45: Bastiane Djamen
A46: Software developer | B46: Nirmin Almalla
A47: Software developer | B47: Arpita Halder
A48: Software developer | B48: Syed Affan Hussain
A49: Software developer | B49: Masum Billah
A50: Software developer | B50: Samuel Ouabo

Sheet Product Goal
A1: Product Vision | B1: Project Mission
A3: Managing building portfolios often means navigating scattered, inconsistent document repositories. Our system enables facility managers to easily upload files, automatically extract and validate critical metadata, classify documents by type and building, and find exactly what they need through intuitive search and natural-language queries — reducing search times from hours to seconds. By integrating into broader building document management platforms, our solution enhances existing workflows and ensures seamless access to critical information across systems. | B3: We aim to build a secure, multi-tenant backend that stores uploaded permits, certificates, and maintenance reports; applies AI-driven OCR and metadata extraction to classify and validate each document; and provides a web UI where users can query and filter their building records using plain language. By implementing and demonstrating a full workflow — from document upload to automatic processing and natural-language search on sample data — we will create the technical foundation for a production-ready system that significantly reduces the time and effort required to manage building documents.

Sheet Product Glossary
A1: Term | B1: Definition
A2: Document | B2: A term to describe arbritrary files that contain information about a Building (e.g. Energieausweis, floor plan, ...)
A3: Building | B3: Corresponds to a real world building object and is described by one ore more Documents
A4: Organization | B4: An Organization is a high level data entity that is responsible for building one or more buildings and managing the corresponding data
A5: User | B5: A system user that belongs to one organization and interacts with the Document data
A6: OpenAPI Client | B6: Tool that handles interactions with APIs defined by OpenAPI specifications
A7: File Explorer | B7: Interface to browse Documents
A8: Ollama | B8: Tool for running LLMs locally or on premise
A9: JWT | B9: JSON Web Token used for secure user authentication
A10: Chatbot | B10: Interface to communicate with LLM
A11: Energieausweis | B11: Energy certificate showing a building’s energy efficiency
A12: Document Meta Data | B12: Information about Document files including knowledge that has been extracted from the Documents content
A13: Key Information | B13: Each Document Category has a set of Key Information that are important and should always be automatically extracted on upload

Sheet Sprint Goals
A1: Sprint # | B1: Sprint goal
A2: 1 | B2: Get to know the team and understand the stakeholder's requirements
A3: =A2+1 -> 2 | B3: Start scaffolding basic backend and frontend infrastructure and research domain-specific knowledge
A4: =A3+1 -> 3 | B4: Set up unified development and production environment through containerization and tooling
A5: =A4+1 -> 4 | B5: Fix the issue of sensitive documents in the repository and enhance backend with endpoints and database connection
A6: =A5+1 -> 5 | B6: Extend and prepare components so they can be easily connected
A7: =A6+1 -> 6 | B7: Prepare mid-project release by binding frontend and backend together and finalizing container orchestration
A8: =A7+1 -> 7 | B8: Refactor and enhance frontend to improve application data flow
A9: =A8+1 -> 8 | B9: Initiate automatic Building detection and general code refactorings
A10: =A9+1 -> 9 | B10: Classify Document automatically into a Building Document Category
A11: =A10+1 -> 10 | B11: Enhance frontend based on workshop and Collect list of relevant information per document category
A12: =A11+1 -> 11 | B12: Auto-Extract and display information from Document based on Document Category
A13: =A12+1 -> 12 | B13: AI chatbot can answer questions based on database information
A14: =A13+1 -> 13 | B14: Prepare Demo Day and Project Hand-Over
A15: =A14+1 -> 14
A16: =A15+1 -> 15

Sheet Velocity Tracking
A1: Sprint # | B1: Story Points Realized | C1: Average
A2: 1 | B2: ='Mid-Project Release plan'!F9 -> 3 | C2: =AVERAGE(B2:B16) -> 21.571429
A3: =A2+1 -> 2 | B3: ='Mid-Project Release plan'!F10 -> 15 | C3: =$C2 -> 21.571429
A4: =A3+1 -> 3 | B4: ='Mid-Project Release plan'!F11 -> 24 | C4: =$C2 -> 21.571429
A5: =A4+1 -> 4 | B5: ='Mid-Project Release plan'!F12 -> 51 | C5: =$C2 -> 21.571429
A6: =A5+1 -> 5 | B6: ='Mid-Project Release plan'!F13 -> 18 | C6: =$C2 -> 21.571429
A7: =A6+1 -> 6 | B7: ='Mid-Project Release plan'!F14 -> 40 | C7: =$C2 -> 21.571429
A8: =A7+1 -> 7 | B8: ='Final Project Release plan'!F9 -> 0 | C8: =$C2 -> 21.571429
A9: =A8+1 -> 8 | C9: =$C2 -> 21.571429
A10: =A9+1 -> 9 | C10: =$C2 -> 21.571429
A11: =A10+1 -> 10 | C11: =$C2 -> 21.571429
A12: =A11+1 -> 11 | C12: =$C2 -> 21.571429
A13: =A12+1 -> 12 | C13: =$C2 -> 21.571429
A14: =A13+1 -> 13 | C14: =$C2 -> 21.571429
A15: =A14+1 -> 14 | C15: =$C2 -> 21.571429
A16: =A15+1 -> 15 | C16: =$C2 -> 21.571429

Sheet Mid-Project Release plan
A1: Sprint | B1: Goal | C1: Feature Name | D1: Est. size | E1: Est. remaining | F1: Real size | G1: Real remaining
A3: Release
A5: Total | D5: =SUM(D8:D15) -> 125 | E5: =D5 -> 125 | F5: =SUM(F8:F15) -> 151 | G5: =F5 -> 151
A7: Sprints
E8: Estimated burn-down | G8: Real burn-down
A9: 1 | B9: ='Sprint Goals'!B2 -> Get to know the team and understand the stakeholder's requirements | D9: =sum(D18:D22) -> 3 | E9: =$D$5 -> 125 | F9: =sum(F18:F22) -> 3 | G9: =$D$5 -> 125
A10: =A9+1 -> 2 | B10: ='Sprint Goals'!B3 -> Start scaffolding basic backend and frontend infrastructure and research domain-specific knowledge | D10: =sum(D23:D30) -> 16 | E10: =E9-D9 -> 122 | F10: =sum(F23:F30) -> 15 | G10: =G9-F9 -> 122
A11: =A10+1 -> 3 | B11: ='Sprint Goals'!B4 -> Set up unified development and production environment through containerization and tooling | D11: =sum(D32:D42) -> 16 | E11: =E10-D10 -> 106 | F11: =sum(F32:F42) -> 24 | G11: =G10-F10 -> 107
A12: 4 | B12: ='Sprint Goals'!B5 -> Fix the issue of sensitive documents in the repository and enhance backend with endpoints and database connection | D12: =SUM(D44:D53) -> 43 | E12: =E11-D11 -> 90 | F12: =SUM(F44:F53) -> 51 | G12: =G11-F11 -> 83
A13: 5 | B13: ='Sprint Goals'!B6 -> Extend and prepare components so they can be easily connected | D13: =SUM(D54:D58) -> 15 | E13: =E12-D12 -> 47 | F13: =SUM(F54:F58) -> 18 | G13: =G12-F12 -> 32
A14: 6 | B14: ='Sprint Goals'!B7 -> Prepare mid-project release by binding frontend and backend together and finalizing container orchestration | D14: =SUM(D61:D77) -> 32 | E14: =E13-D13 -> 32 | F14: =SUM(F61:F77) -> 40 | G14: =G13-F13 -> 14
A16: Features
A18: =A9 -> 1 | B18: =B9 -> Get to know the team and understand the stakeholder's requirements
C19: Align on Development Guidelines | D19: 1 | F19: 1
C20: Meet the industry partner | D20: 1 | F20: 1
C21: Create a team logo | D21: 1 | F21: 1
A23: =A10 -> 2 | B23: =B10 -> Start scaffolding basic backend and frontend infrastructure and research domain-specific knowledge
C24: Create a shirt design | D24: 1 | F24: 1
C25: Initialize SW Bill of Materials | D25: 2 | F25: 2
C26: Create SW Architecture Description | D26: 3 | F26: 3
C27: Scaffold Basic C# Web API | D27: 3 | F27: 2
C28: Scaffold Basic Angular Application | D28: 3 | F28: 3
C29: Research Local RAG-Based LLM Solutions | D29: 2 | F29: 2
C30: Research typical Building Documents | D30: 2 | F30: 2
A32: =A11 -> 3 | B32: =B11 -> Set up unified development and production environment through containerization and tooling
C33: Dockerize Front-End | D33: 2 | F33: 3
C34: Dockerize Back-End | D34: 2 | F34: 2
C35: Create DB Scheme Diagram | D35: 2 | F35: 2
C36: Create README | D36: 1 | F36: 1
C37: Consolidate Project Structure | D37: 2 | F37: 2
C38: Create Docker-Compose File | D38: 2 | F38: 3
C39: Linting and Formatting Frontend | D39: 1 | F39: 1
C40: Linting and Formatting Backend | D40: 1 | F40: 2
C41: Set Up GitHub Actions Pipeline | D41: 3 | F41: 8
A43: 4 | B43: =B12 -> Fix the issue of sensitive documents in the repository and enhance backend with endpoints and database connection
C44: Fix: Remove Sensitive Building Documents | D44: 5 | F44: 5
C45: Implement Backend CRUD for Document | D45: 8 | F45: 8
C46: Implement Backend CRUD for Building | D46: 5 | F46: 8
C47: Integrate Linting into Pipeline | D47: 5 | F47: 8
C48: Add Authentication to Frontend | D48: 3 | F48: 5
...

Sheet Final Project Release plan
A1: Sprint | B1: Goal | C1: Feature Name | D1: Est. size | E1: Est. remaining | F1: Real size | G1: Real remaining
A3: Release
A5: Total | D5: =SUM(D8:D16) -> 190 | E5: =D5 -> 190 | F5: =SUM(F8:F16) -> 0 | G5: =F5 -> 0
A7: Sprints
E8: Estimated burn-down | G8: Real burn-down
A9: 7 | B9: ='Sprint Goals'!B8 -> Refactor and enhance frontend to improve application data flow | D9: =sum(D19:D36) -> 56 | E9: =$D$5 -> 190 | F9: =sum(F19:F36) -> 0 | G9: =$D$5 -> 190
A10: 8 | B10: ='Sprint Goals'!B9 -> Initiate automatic Building detection and general code refactorings | D10: =sum(D38:D45) -> 21 | E10: =E9-D9 -> 134 | F10: =sum(F38:F45) -> 0 | G10: =G9-F9 -> 190
A11: 9 | B11: ='Sprint Goals'!B10 -> Classify Document automatically into a Building Document Category | D11: =sum(D47:D57) -> 34 | E11: =E10-D10 -> 113 | F11: =sum(F47:F57) -> 0 | G11: =G10-F10 -> 190
A12: 10 | B12: ='Sprint Goals'!B11 -> Enhance frontend based on workshop and Collect list of relevant information per document category | D12: =SUM(D59:D68) -> 26 | E12: =E11-D11 -> 79 | F12: =SUM(F59:F68) -> 0 | G12: =G11-F11 -> 190
A13: 11 | B13: ='Sprint Goals'!B12 -> Auto-Extract and display information from Document based on Document Category | D13: =SUM(D69:D73) -> 15 | E13: =E12-D12 -> 53 | F13: =SUM(F69:F73) -> 0 | G13: =G12-F12 -> 190
A14: 12 | B14: ='Sprint Goals'!B13 -> AI chatbot can answer questions based on database information | D14: =SUM(D76:D82) -> 23 | E14: =E13-D13 -> 38 | F14: =SUM(F76:F82) -> 0 | G14: =G13-F13 -> 190
A15: 13 | B15: ='Sprint Goals'!B14 -> Prepare Demo Day and Project Hand-Over | D15: =SUM(D83:D90) -> 15 | E15: =E14-D14 -> 15 | F15: =SUM(F83:F90) -> 0 | G15: =G14-F14 -> 190
A17: Features
A19: =A9 -> 7 | B19: =B9 -> Refactor and enhance frontend to improve application data flow
C20: Connect Frontend to LLM | D20: 3
C21: Update Bill of Materials | D21: 1
C22: Adopt Feature Branch Workflow and Clean Up Branches | D22: 2
C23: Support OpenAPI Client Generation | D23: 8
C24: Replace Default Web Services with Angular Frontend | D24: 3
C25: Display Stored Documents in Explorer | D25: 3
C26: Gather sample files of building documents | D26: 2
C27: Display JPG/PNG Files in Frontend | D27: 3
C28: Create a Building Form | D28: 5
C29: Implement Backend Logging | D29: 3
C30: Implement User Authentication in Backend | D30: 5
C31: Refactor: Enforce OpenAPI SDK Usage | D31: 2
... C36: Enforce HTTPS on Production Server | D36: 3
A38: =A10 -> 8 | B38: =B10 -> Initiate automatic Building detection and general code refactorings
C39: Implement OCR using Tika | D39: 3
C40: Production Bug: AI Assistant Not Working | D40: 2
C41: Detect a Building from a Document | D41: 5
C42: Popup Window on Document Upload | D42: 5
C43: Refactor Building Entity | D43: 2
C44: Refactor Repository Structure and Cleanup | D44: 1
C45: Implement Session-Based Authentication for Frontend | D45: 3
A47: =A11 -> 9 | B47: =B11 -> Classify Document automatically into a Building Document Category
C48: CRUD Endpoints for Document Categories | D48: 3
C49: Auto-Detect Document Category from Uploaded Document | D49: 8
C50: Enhance Frontend Design | D50: 5
C51: Remove FastAPI from Ollama container | D51: 3
...

Sheet Definition of Done
A1: # | B1: Feature Definition of Done | C1: Sprint Release Definition of Done | D1: Project Release Definition of Done
A2: 1 | B2: Documentation is updated to include the new feature | C2: Atleast one error-free functionality (which has passed feature DoD), more than previous release. | D2: Stakeholders have reviewed and signed off the release
A3: 2 | B3: Another SD, not the implementer, has reviewed the feature using the documentation. | C3: Entire project builds and deploys to production. | D3: Documentation (user + technical) is complete and comprehensive
A4: 3 | B4: GitHub actions workflows for linting pass | C4: Non-UI logic (e.g., DB transactions) verified by an SD or RM. | D4: No critical open issues remain in backlog
A5: 4 | B5: Feature branch has been merged and deleted | C5: Release manager writes release notes (& Change log)
A6: 5 | C6: All GitHub actions workflows pass
A7: 6 | C7: Bill of Materials is up to date

Sheet Documentation
A1: Type | B1: Link / reference
A2: User Documentation | B2: https://github.com/amosproj/amos2025ss02-building-documentation-management-system/wiki/User-Documentation
A3: Build and Deploy Documentation | B3: https://github.com/amosproj/amos2025ss02-building-documentation-management-system/wiki/Build-&-Deploy
A4: Technical Documentation | B4: https://github.com/amosproj/amos2025ss02-building-documentation-management-system/wiki/Technical-Design

Sheet Bill of Materials
A1: # | B1: Context | C1: Name | D1: Version | E1: License | F1: Comment
A2: 1 | B2: UI | C2: Angular | D2: 19 | E2: MIT License | F2: Needed for developing UI as per client requirement
A3: 2 | B3: UI | C3: Node.js | D3: 22.15.0 | E3: Custom (open-source) | F3: Needed for Angular
A4: 3 | B4: UI | C4: npm | D4: 10.9.2 | E4: Artistic License 2.0 with additions | F4: Package manager, needed for Angular
A5: 4 | B5: Backend (Framework) | C5: Microsoft.NETCore.App | D5: Implicit | E5: MIT License | F5: .NET Core base runtime (System., Microsoft.)
A6: 5 | B6: Backend (Framework) | C6: Microsoft.ASPNetCore.App | D6: Implicit | E6: MIT License | F6: ASP.NET Core web framework (Controllers, Routing, Authorization)
A7: 6 | B7: Backend (Library) | C7: Swashbuckle.AspNetCore | D7: 6.5.0 | E7: MIT License | F7: Provides Swagger/OpenAPI documentation and UI
A8: 7 | B8: Backend (Library) | C8: AspNetCore.HealthChecks.UI | D8: 6.0.4 | E8: Apache 2.0 License | F8: Adds health check endpoints (/healthz) and optional health UI
A9: 8 | B9: Backend (Framework) | C9: Entity Framework Core .NET Command-Line Tools | D9: 9.0.4 | E9: Apache 2.0 License | F9: Used to manage EF Core database tasks from the terminal

Sheet Planning Poker
A1: ='Project Team'!A1 -> Last Name | B1: ='Project Team'!B1 -> First Name | C1: Value
A2: ='Project Team'!A5 -> Halder | B2: ='Project Team'!B5 -> Arpita | C2: 1 | E2: =average(C2:C10) -> 1 | F2: =if(stdev(C2:C7) > 0,"NOK", "OK") -> OK
A3: ='Project Team'!A6 -> Kazi | B3: ='Project Team'!B6 -> Masudur Rahaman | C3: 1
A4: ='Project Team'!A8 -> Ouabo | B4: ='Project Team'!B8 -> Samuel | C4: 1
A5: ='Project Team'!A9 -> Billah | B5: ='Project Team'!B9 -> Masum | C5: 1
A6: ='Project Team'!A10 -> Hussain | B6: ='Project Team'!B10 -> Syed Affan | C6: 1 | E6: 0 | F6: No size
A7: ='Project Team'!A11 -> Djamen | B7: ='Project Team'!B11 -> Bastiane | C7: 1 | E7: 1 | F7: Trivial size
E8: 2 | F8: Small size
A9: ='Project Team'!A12 | B9: ='Project Team'!B12 | E9: 3 | F9: Medium size
A10: ='Project Team'!A13 | B10: ='Project Team'!B13 | E10: 5 | F10: Large size
E11: 8 | F11: Very large size
E12: 13 | F12: Too large (size)
A14: How to play planning poker
A16: 1. Everyone type their number into their value field, don't hit return yet
A17: 2. Someone, perhaps a product owner, count down 3.. 2.. 1..
A18: 3. Then, everyone hit return to submit their value
